#VRML_SIM R2021a utf8
WorldInfo {
  info [
    "Benchmark objective: "
    "learn how to program a robot."
  ]
  title "Robot Programming"
  window "robot_programming"
  basicTimeStep 20
  FPS 30
  optimalThreadCount 4
  coordinateSystem "NUE"
  gpsCoordinateSystem "WGS84"
  gpsReference 37.9514 -91.769 0
  contactProperties [
    ContactProperties {
      material2 "thymio body"
      coulombFriction [
        0.7
      ]
    }
  ]
}
Viewpoint {
  orientation 0.09088498247671667 -0.9906198801513317 -0.10204005590535511 4.524044374088049
  position 11.676712440242953 5.024247415532802 -9.455127720112444
  followType "None"
}
TexturedBackground {
}
TexturedBackgroundLight {
}
Transform {
  translation 0 0 0.25
  children [
    Shape {
      appearance PBRAppearance {
        baseColor 0.8 0.8 0.8
        baseColorMap ImageTexture {
          url [
            "textures/target.png"
          ]
        }
        roughness 0.5
        metalness 0
      }
      geometry IndexedFaceSet {
        coord Coordinate {
          point [
            0.125 0.0001 0.125
            0.125 0.0001 -0.125
            -0.125 0.0001 -0.125
            -0.125 0.0001 0.125
          ]
        }
        coordIndex [
          0, 1, 2, 3
        ]
      }
    }
  ]
}
UnevenTerrain {
  randomSeed 5
}
Robot {
  translation 4.264601792021319 1.75020413526944 -7.677323054231226
  rotation -0.09022522380245417 -0.9945310149335388 -0.05260674220156758 0.8071935705343564
  scale 5 5 5
  children [
    Pen {
      translation 0 -0.016 0
    }
    Compass {
      rotation 0 -1 0 1.5708
    }
    GPS {
      rotation 0 -1 0 1.5708
    }
    RangeFinder {
      translation 0 0.05 0.075
      rotation 0 1 0 3.14159
      fieldOfView 1.48
      width 640
      height 360
      maxRange 10
    }
    InertialUnit {
      rotation 0 -1 0 1.5708
    }
    Camera {
      translation 0 0.05 0.075
      rotation 0 1 0 3.14159
      fieldOfView 1.48
      width 1280
      height 720
    }
    Solid {
      translation 0.07 0.0300007 0.03
      rotation 0.5773502691890485 -0.5773492691885823 -0.5773512691895147 -2.094395307179586
      scale 0.003 0.003 0.003
      children [
        DEF BODY Shape {
          appearance PBRAppearance {
            baseColor 0.917647 0.145098 0.145098
            roughness 1
            metalness 0
          }
          geometry Mesh {
            url [
              "C:/Users/elive/RoverSoftware/Autonomy_Simulator/webots_sim/protos/Frame.stl"
            ]
          }
        }
      ]
      name "solid(4)"
    }
    DEF WHEEL1 HingeJoint {
      jointParameters HingeJointParameters {
        position 1451.573141027909
        anchor 0.06 0 0.05
      }
      device [
        RotationalMotor {
          name "wheel1"
        }
      ]
      endPoint Solid {
        translation 0.06054761704010703 0.00039195130243222117 0.050363064302337716
        rotation 0.11773000429104448 -0.12477840937113177 -0.9851751086200062 4.707524716965568
        scale 0.5 0.5 0.5
        children [
          DEF WHEEL Shape {
            appearance PBRAppearance {
              roughness 1
              metalness 0
            }
            geometry Cylinder {
              height 0.02
              radius 0.04
              subdivision 24
            }
          }
        ]
        boundingObject USE WHEEL
        physics Physics {
        }
        linearVelocity 9.249979014852012e-05 -9.682184735723451e-06 -8.531832595474509e-05
        angularVelocity -2.0268774417736538e-05 1.548296979967128e-06 -2.0489653075727767e-05
      }
    }
    DEF WHEEL2 HingeJoint {
      jointParameters HingeJointParameters {
        position 918.7179261681908
        anchor -0.06 0 0.05
      }
      device [
        RotationalMotor {
          name "wheel2"
        }
      ]
      endPoint Solid {
        translation -0.05947725206290657 1.4817420786140134e-05 0.050296758595357385
        rotation -0.5323512348332933 0.5305174784624784 -0.6596615555095519 4.313972583634613
        scale 0.5 0.5 0.5
        children [
          USE WHEEL
        ]
        name "solid(1)"
        boundingObject USE WHEEL
        physics Physics {
        }
        linearVelocity 9.191874337687066e-05 -9.905907776537235e-06 -8.47606886594817e-05
        angularVelocity -2.0163062741136542e-05 1.5467115848727366e-06 -2.0379998444664887e-05
      }
    }
    DEF WHEEL3 HingeJoint {
      jointParameters HingeJointParameters {
        position 1451.6090326975884
        anchor 0.06 0 -0.05
      }
      device [
        RotationalMotor {
          name "wheel3"
        }
      ]
      endPoint Solid {
        translation 0.05952885366601636 0.00021794380741295 -0.05007522002832716
        rotation -0.0399622158028865 0.04540615263618315 0.998168974979138 1.5678566870125095
        scale 0.5 0.5 0.5
        children [
          USE WHEEL
        ]
        name "solid(2)"
        boundingObject USE WHEEL
        physics Physics {
        }
        linearVelocity 9.205852512543308e-05 -9.52515217848267e-06 -8.573882224168285e-05
        angularVelocity -1.610557127438753e-05 1.48642583966744e-06 -1.6171554097420465e-05
      }
    }
    DEF WHEEL4 HingeJoint {
      jointParameters HingeJointParameters {
        position 918.7705474948426
        anchor -0.06 0 -0.05
      }
      device [
        RotationalMotor {
          name "wheel4"
        }
      ]
      endPoint Solid {
        translation -0.06074266137421675 0.0004800222598876055 -0.0498052912404009
        rotation -0.544620935193605 0.5427150350647614 -0.6394125645180097 4.285991311539706
        scale 0.5 0.5 0.5
        children [
          USE WHEEL
        ]
        name "solid(3)"
        boundingObject USE WHEEL
        physics Physics {
        }
        linearVelocity 9.154592891678585e-05 -9.72028404335208e-06 -8.524595167003599e-05
        angularVelocity -1.8609701138384243e-05 1.523664522562673e-06 -1.876883554440554e-05
      }
    }
  ]
  boundingObject Box {
    size 0.1 0.011982918352612417 0.1
  }
  physics Physics {
    density -1
    mass 1
  }
  controller "move"
  linearVelocity 9.197731442472595e-05 -9.733146206453967e-06 -8.523962584117996e-05
  angularVelocity 3.1113024924756985e-08 1.246432999788893e-06 5.655399678977224e-07
}
Oak {
  translation -7.52 1.9 0.52
}
Oak {
  translation -7.66 1.9 -10.6
  name "oak tree(1)"
}
OilBarrel {
  translation -1.11 2.19 -3.53
  height 0.4
  radius 0.15
}
DEF AR_Tag Solid {
  translation -8.14806 2.73 -0.717704
  rotation 0.9831056944488314 -0.1294279597735375 -0.1294279597735375 -1.5878353071795859
  scale 20 20 20
  children [
    Solid {
      scale 0.005 0.005 0.005
      children [
        DEF SHAPE Shape {
          appearance PBRAppearance {
            baseColorMap ImageTexture {
              url [
                "C:/Users/elive/Downloads/gazebo_models-master/ar_tags/model/marker0/materials/textures/Marker0.png"
              ]
            }
            roughness 1
            metalness 0
            name "Marker0Mat"
          }
          geometry IndexedFaceSet {
            coord Coordinate {
              point [
                1 1 -9.41753e-06
                1 -1 -9.41753e-06
                -1 -1 -9.41753e-06
                -1 1 1.99999
                -1 -1 1.99999
                0.999999 -1 1.99999
                1 0.999999 1.99999
                0.999999 -1 1.99999
                1 -1 -9.41753e-06
                0.999999 -1 1.99999
                -1 -1 1.99999
                -1 -1 -9.41753e-06
                -1 -1 -9.41753e-06
                -1 -1 1.99999
                -1 1 1.99999
                1 1 -9.41753e-06
                -1 1 -9.41753e-06
                -1 1 1.99999
                -1 1 -9.41753e-06
                1 0.999999 1.99999
                1 1 -9.41753e-06
                1 -1 -9.41753e-06
                -1 1 -9.41753e-06
                1 0.999999 1.99999
              ]
            }
            normal Normal {
              vector [
                0 0 -1
                0 0 -1
                0 0 -1
                0 0 1
                0 0 1
                0 0 1
                1 -5.66244e-07 3.27825e-07
                1 -5.66244e-07 3.27825e-07
                1 -5.66244e-07 3.27825e-07
                -4.76837e-07 -1 0
                -4.76837e-07 -1 0
                -4.76837e-07 -1 0
                -1 2.38419e-07 -1.19209e-07
                -1 2.38419e-07 -1.19209e-07
                -1 2.38419e-07 -1.19209e-07
                2.38419e-07 1 1.78814e-07
                2.38419e-07 1 1.78814e-07
                2.38419e-07 1 1.78814e-07
                0 0 -1
                0 0 1
                1 0 -2.38419e-07
                0 -1 -2.98023e-07
                -1 2.38419e-07 0
                2.98023e-07 1 2.38418e-07
              ]
            }
            texCoord TextureCoordinate {
              point [
                0 0
                0 0
                0 0
                0 0
                0 0
                0 0
                0.9999 0.994019
                9.96856e-05 0.994019
                0.000100079 9.97642e-05
                0 0
                0 0
                0 0
                9.96856e-05 0.994019
                9.98823e-05 9.96856e-05
                0.9999 9.98429e-05
                0 0
                0 0
                0 0
                0 0
                0 0
                0.9999 9.96856e-05
                0 0
                0.9999 0.994019
                0 0
              ]
            }
            coordIndex [
              0, 1, 2, -1, 3, 4, 5, -1, 6, 7, 8, -1, 9, 10, 11, -1, 12, 13, 14, -1, 15, 16, 17, -1, 18, 0, 2, -1, 19, 3, 5, -1, 20, 6, 8, -1, 21, 9, 11, -1, 22, 12, 14, -1, 23, 15, 17, -1
            ]
          }
        }
      ]
      name "Marker0"
      boundingObject USE SHAPE
    }
  ]
  description "AR Tag"
}
