#VRML_SIM R2021a utf8
WorldInfo {
  info [
    "Benchmark objective: "
    "learn how to program a robot."
  ]
  title "Robot Programming"
  window "robot_programming"
  basicTimeStep 20
  FPS 30
  optimalThreadCount 4
  coordinateSystem "NUE"
  gpsCoordinateSystem "WGS84"
  gpsReference 37.9514 -91.769 0
  contactProperties [
    ContactProperties {
      material2 "thymio body"
      coulombFriction [
        0.7
      ]
    }
  ]
}
Viewpoint {
  orientation 0.06886283690441623 -0.9944640183047908 -0.079367663381029 4.484304427312322
  position -1.4778276356690363 2.4418554457644808 -5.27445272549834
  followType "None"
}
TexturedBackground {
}
TexturedBackgroundLight {
}
Transform {
  translation 0 0 0.25
  children [
    Shape {
      appearance PBRAppearance {
        baseColor 0.8 0.8 0.8
        baseColorMap ImageTexture {
          url [
            "textures/target.png"
          ]
        }
        roughness 0.5
        metalness 0
      }
      geometry IndexedFaceSet {
        coord Coordinate {
          point [
            0.125 0.0001 0.125
            0.125 0.0001 -0.125
            -0.125 0.0001 -0.125
            -0.125 0.0001 0.125
          ]
        }
        coordIndex [
          0, 1, 2, 3
        ]
      }
    }
  ]
}
UnevenTerrain {
  randomSeed 5
}
Robot {
  translation -2.878030542950281 2.162849623228724 -4.970385815055909
  rotation -0.008925965162783097 -0.9996018828408382 -0.026765705052623243 1.5673696557438486
  children [
    InertialUnit {
      translation 0.03 0 1.10196e-07
      rotation 0 -1 0 1.5708
    }
    GPS {
      translation 0.06 0 -4.40784e-07
      rotation 0 -1 0 1.57079
    }
    Pen {
      translation 0 -0.04 0
    }
    Compass {
      rotation 0 1 0 -1.5707953071795862
    }
    Camera {
      translation 0.04 0.17 0.29
      rotation 0 1 0 3.14159
      fieldOfView 1.48353
      width 1280
      height 720
    }
    RangeFinder {
      translation 7.96077e-08 0.2 0.27
      rotation 0 1 0 3.14159
      fieldOfView 1.48
      width 640
      height 360
      maxRange 10
    }
    DEF Wheel4 Transform {
      translation -0.11 0 -0.28
      children [
        DEF WHEEL4 HingeJoint {
          jointParameters HingeJointParameters {
            position 829.7530181205905
            anchor -0.06 0 -0.05
          }
          device [
            RotationalMotor {
              name "wheel4"
            }
          ]
          endPoint Solid {
            translation -0.060028091164745945 6.569911609270603e-05 -0.05021402999246991
            rotation -0.18142399624335995 0.1828449645626842 -0.9662572393111267 4.675608930512544
            children [
              DEF WHEEL Shape {
                appearance PBRAppearance {
                  baseColor 0.305882 0.898039 0.25098
                  roughness 1
                  metalness 0
                }
                geometry Cylinder {
                  height 0.02
                  radius 0.04
                  subdivision 24
                }
              }
            ]
            name "solid(2)"
            boundingObject USE WHEEL
            physics Physics {
              density -1
              mass 0.175
            }
            linearVelocity -0.03197857995262476 0.002083413445478068 0.0018089767310645619
            angularVelocity 0.004051428744908961 -0.017111317240192186 0.8020951874077578
          }
        }
      ]
    }
    DEF Wheel2 Transform {
      translation -0.1 0 0.21
      children [
        DEF WHEEL2 HingeJoint {
          jointParameters HingeJointParameters {
            position 520.6151611133058
            anchor -0.06 0 0.05
          }
          device [
            RotationalMotor {
              name "wheel2"
            }
          ]
          endPoint Solid {
            translation -0.06002746720517216 0.00013853078942290515 0.05007966717466687
            rotation -0.3974242875613898 0.3952441244826689 0.8281521706294381 1.7578144241453462
            children [
              DEF WHEEL Shape {
                appearance PBRAppearance {
                  baseColor 0.305882 0.898039 0.25098
                  roughness 1
                  metalness 0
                }
                geometry Cylinder {
                  height 0.02
                  radius 0.04
                  subdivision 24
                }
              }
            ]
            name "solid(6)"
            boundingObject USE WHEEL
            physics Physics {
              density -1
              mass 0.175
              centerOfMass [
                0.07 -0.03 0
              ]
            }
            linearVelocity -0.06547075969028575 0.04573142226132011 0.001289905673019591
            angularVelocity 0.0040514614016125055 -0.017111064852279895 0.8020978107090665
          }
        }
      ]
    }
    DEF Wheel1 Transform {
      translation 0.19 0 0.21
      children [
        DEF WHEEL1 HingeJoint {
          jointParameters HingeJointParameters {
            position 2574.133387488796
            anchor 0.06 0 0.05
          }
          device [
            RotationalMotor {
              name "wheel1"
            }
          ]
          endPoint Solid {
            translation 0.06004158266570769 4.485253124980051e-05 0.0498357199023657
            rotation 0.6927792393758823 -0.6931795374242392 -0.19889458108780006 3.53443466198022
            children [
              DEF WHEEL Shape {
                appearance PBRAppearance {
                  baseColor 0.305882 0.898039 0.25098
                  roughness 1
                  metalness 0
                }
                geometry Cylinder {
                  height 0.02
                  radius 0.04
                  subdivision 24
                }
              }
            ]
            name "solid(5)"
            boundingObject USE WHEEL
            physics Physics {
            }
            linearVelocity -0.03275918532891867 0.0018317023004982452 0.00015785044867834555
            angularVelocity 0.03664669700498294 -0.18149832422836357 10.000569049477589
          }
        }
      ]
    }
    DEF Frame Solid {
      translation 0.25 0.120001 0.13
      rotation 0.5773502691890485 -0.5773492691885823 -0.5773512691895147 -2.094395307179586
      scale 0.01 0.01 0.01
      children [
        DEF BODY Shape {
          appearance PBRAppearance {
            baseColor 0 0 0
            roughness 1
            metalness 0
          }
          geometry Mesh {
            url [
              "C:/Users/elive/RoverSoftware/Autonomy_Simulator/webots_sim/Frame.stl"
            ]
          }
        }
      ]
      name "solid(4)"
    }
    DEF Wheel3 Transform {
      translation 0.17 0 -0.29
      children [
        DEF WHEEL3 HingeJoint {
          jointParameters HingeJointParameters {
            position 2054.266482058161
            anchor 0.06 0 -0.05
          }
          device [
            RotationalMotor {
              name "wheel3"
            }
          ]
          endPoint Solid {
            translation 0.06004582815690096 -0.00014124126081029349 -0.04998898946961713
            rotation -0.41756304732283245 0.4180311357167524 0.8067782043919083 1.7838130918623132
            children [
              USE WHEEL
            ]
            name "solid(1)"
            boundingObject USE WHEEL
            physics Physics {
            }
            linearVelocity -0.03178350886528931 0.0006877976382830369 0.0017824803117805737
            angularVelocity 0.03664728243921042 -0.1814989178199989 10.000567218510104
          }
        }
      ]
    }
  ]
  boundingObject Box {
    size 0.1 0.031156457259617416 0.1
  }
  physics Physics {
    density -1
    mass 1
  }
  controller "move"
  linearVelocity -0.03242458239264383 0.0009795796920673587 0.0008690718390764357
  angularVelocity 0.001225949519881038 -0.002834007874084578 0.0022282874004519505
}
Oak {
  translation -7.52 1.9 0.52
}
Oak {
  translation -7.66 1.9 -10.6
  name "oak tree(1)"
}
OilBarrel {
  translation -9.28 3.3 4.82
}
DEF AR_Tag Solid {
  translation 3.67951 2.39 5.48237
  rotation 0.9831056944488314 -0.1294279597735375 -0.1294279597735375 -1.5878353071795859
  scale 20 20 20
  children [
    Solid {
      scale 0.005 0.005 0.005
      children [
        DEF SHAPE Shape {
          appearance PBRAppearance {
            baseColorMap ImageTexture {
              url [
                "C:/Users/elive/Downloads/gazebo_models-master/ar_tags/model/marker0/materials/textures/Marker0.png"
              ]
            }
            roughness 1
            metalness 0
            name "Marker0Mat"
          }
          geometry IndexedFaceSet {
            coord Coordinate {
              point [
                1 1 -9.41753e-06
                1 -1 -9.41753e-06
                -1 -1 -9.41753e-06
                -1 1 1.99999
                -1 -1 1.99999
                0.999999 -1 1.99999
                1 0.999999 1.99999
                0.999999 -1 1.99999
                1 -1 -9.41753e-06
                0.999999 -1 1.99999
                -1 -1 1.99999
                -1 -1 -9.41753e-06
                -1 -1 -9.41753e-06
                -1 -1 1.99999
                -1 1 1.99999
                1 1 -9.41753e-06
                -1 1 -9.41753e-06
                -1 1 1.99999
                -1 1 -9.41753e-06
                1 0.999999 1.99999
                1 1 -9.41753e-06
                1 -1 -9.41753e-06
                -1 1 -9.41753e-06
                1 0.999999 1.99999
              ]
            }
            normal Normal {
              vector [
                0 0 -1
                0 0 -1
                0 0 -1
                0 0 1
                0 0 1
                0 0 1
                1 -5.66244e-07 3.27825e-07
                1 -5.66244e-07 3.27825e-07
                1 -5.66244e-07 3.27825e-07
                -4.76837e-07 -1 0
                -4.76837e-07 -1 0
                -4.76837e-07 -1 0
                -1 2.38419e-07 -1.19209e-07
                -1 2.38419e-07 -1.19209e-07
                -1 2.38419e-07 -1.19209e-07
                2.38419e-07 1 1.78814e-07
                2.38419e-07 1 1.78814e-07
                2.38419e-07 1 1.78814e-07
                0 0 -1
                0 0 1
                1 0 -2.38419e-07
                0 -1 -2.98023e-07
                -1 2.38419e-07 0
                2.98023e-07 1 2.38418e-07
              ]
            }
            texCoord TextureCoordinate {
              point [
                0 0
                0 0
                0 0
                0 0
                0 0
                0 0
                0.9999 0.994019
                9.96856e-05 0.994019
                0.000100079 9.97642e-05
                0 0
                0 0
                0 0
                9.96856e-05 0.994019
                9.98823e-05 9.96856e-05
                0.9999 9.98429e-05
                0 0
                0 0
                0 0
                0 0
                0 0
                0.9999 9.96856e-05
                0 0
                0.9999 0.994019
                0 0
              ]
            }
            coordIndex [
              0, 1, 2, -1, 3, 4, 5, -1, 6, 7, 8, -1, 9, 10, 11, -1, 12, 13, 14, -1, 15, 16, 17, -1, 18, 0, 2, -1, 19, 3, 5, -1, 20, 6, 8, -1, 21, 9, 11, -1, 22, 12, 14, -1, 23, 15, 17, -1
            ]
          }
        }
      ]
      name "Marker0"
      boundingObject USE SHAPE
    }
  ]
  description "AR Tag"
}
